Workbook

Sheet Sales_Data
A1: Date | B1: Month | C1: Quarter | D1: Year | E1: Region | F1: State/City | G1: Sales Executive Name | H1: Product Category | I1: Product Name | J1: Units Sold | K1: Selling Price | L1: Revenue | M1: Cost | N1: Profit | O1: Profit Margin % | P1: Customer Type | Q1: Sales Channel | R1: Target Sales | S1: Actual Sales | T1: Achievement % | U1: Growth % | V1: Previous Period Revenue (Reference)
A2: 45300 | B2: January | C2: Q1 | D2: 2024 | E2: West | F2: Pune | G2: Isha Bose | H2: Apparel | I2: Running Shoes | J2: 149 | K2: 7672.86 | L2: =J2*K2 -> 1143256.1 | M2: =L2*0.5673 -> 648569.21 | N2: =L2-M2 -> 494686.93 | O2: =IFERROR(N2/L2,0) -> 0.4327 | P2: New | Q2: Offline | R2: =L2/(1+-0.1362) -> 1323519.5 | S2: =L2 -> 1143256.1 | T2: =IFERROR(S2/R2,0) -> 0.8638 | U2: =IFERROR((L2-V2)/V2,0) -> 0.2892 | V2: =L2/1.2892 -> 886795.02
A3: 45308 | B3: January | C3: Q1 | D3: 2024 | E3: Central | F3: Raipur | G3: Karan Mehta | H3: Apparel | I3: Women's Kurti | J3: 25 | K3: 5299.36 | L3: =J3*K3 -> 132484 | M3: =L3*0.7392 -> 97932.173 | N3: =L3-M3 -> 34551.827 | O3: =IFERROR(N3/L3,0) -> 0.2608 | P3: Existing | Q3: Online | R3: =L3/(1+0.0976) -> 120703.35 | S3: =L3 -> 132484 | T3: =IFERROR(S3/R3,0) -> 1.0976 | U3: =IFERROR((L3-V3)/V3,0) -> -0.1386 | V3: =L3/0.8614 -> 153800.79
A4: 45310 | B4: January | C4: Q1 | D4: 2024 | E4: Central | F4: Raipur | G4: Nikhil Gupta | H4: Apparel | I4: Women's Kurti | J4: 20 | K4: 6479.14 | L4: =J4*K4 -> 129582.8 | M4: =L4*0.5913 -> 76622.31 | N4: =L4-M4 -> 52960.49 | O4: =IFERROR(N4/L4,0) -> 0.4087 | P4: Existing | Q4: Online | R4: =L4/(1+0.1587) -> 111834.64 | S4: =L4 -> 129582.8 | T4: =IFERROR(S4/R4,0) -> 1.1587 | U4: =IFERROR((L4-V4)/V4,0) -> 0.2551 | V4: =L4/1.2551 -> 103245
A5: 45310 | B5: January | C5: Q1 | D5: 2024 | E5: East | F5: Bhubaneswar | G5: Isha Bose | H5: Home Appliances | I5: Refrigerator 300L | J5: 77 | K5: 2350.9 | L5: =J5*K5 -> 181019.3 | M5: =L5*0.6207 -> 112358.68 | N5: =L5-M5 -> 68660.62 | O5: =IFERROR(N5/L5,0) -> 0.3793 | P5: New | Q5: Online | R5: =L5/(1+-0.0189) -> 184506.47 | S5: =L5 -> 181019.3 | T5: =IFERROR(S5/R5,0) -> 0.9811 | U5: =IFERROR((L5-V5)/V5,0) -> 0.236 | V5: =L5/1.236 -> 146455.74
A6: 45318 | B6: January | C6: Q1 | D6: 2024 | E6: East | F6: Bhubaneswar | G6: Vikram Rao | H6: FMCG | I6: Organic Tea | J6: 264 | K6: 7997.91 | L6: =J6*K6 -> 2111448.2 | M6: =L6*0.5934 -> 1252933.4 | N6: =L6-M6 -> 858514.85 | O6: =IFERROR(N6/L6,0) -> 0.4066 | P6: New | Q6: Offline | R6: =L6/(1+-0.0485) -> 2219073.3 | S6: =L6 -> 2111448.2 | T6: =IFERROR(S6/R6,0) -> 0.9515 | U6: =IFERROR((L6-V6)/V6,0) -> -0.1676 | V6: =L6/0.8324 -> 2536578.9
A7: 45321 | B7: January | C7: Q1 | D7: 2024 | E7: East | F7: Kolkata | G7: Karan Mehta | H7: FMCG | I7: Packaged Snacks | J7: 20 | K7: 6841.85 | L7: =J7*K7 -> 136837 | M7: =L7*0.572 -> 78270.764 | N7: =L7-M7 -> 58566.236 | O7: =IFERROR(N7/L7,0) -> 0.428 | P7: Existing | Q7: Offline | R7: =L7/(1+-0.0718) -> 147421.89 | S7: =L7 -> 136837 | T7: =IFERROR(S7/R7,0) -> 0.9282 | U7: =IFERROR((L7-V7)/V7,0) -> -0.146 | V7: =L7/0.854 -> 160230.68
A8: 45321 | B8: January | C8: Q1 | D8: 2024 | E8: South | F8: Hyderabad | G8: Priya Nair | H8: Home Appliances | I8: Refrigerator 300L | J8: 60 | K8: 3993.13 | L8: =J8*K8 -> 239587.8 | M8: =L8*0.702 -> 168190.64 | N8: =L8-M8 -> 71397.164 | O8: =IFERROR(N8/L8,0) -> 0.298 | P8: Existing | Q8: Online | R8: =L8/(1+0.0987) -> 218064.8 | S8: =L8 -> 239587.8 | T8: =IFERROR(S8/R8,0) -> 1.0987 | U8: =IFERROR((L8-V8)/V8,0) -> -0.1766 | V8: =L8/0.8234 -> 290973.77
A9: 45321 | B9: January | C9: Q1 | D9: 2024 | E9: South | F9: Bengaluru | G9: Isha Bose | H9: Home Appliances | I9: Washing Machine 7kg | J9: 26 | K9: 2191.73 | L9: =J9*K9 -> 56984.98 | M9: =L9*0.6233 -> 35518.738 | N9: =L9-M9 -> 21466.242 | O9: =IFERROR(N9/L9,0) -> 0.3767 | P9: Existing | Q9: Online | R9: =L9/(1+0.181) -> 48251.465 | S9: =L9 -> 56984.98 | T9: =IFERROR(S9/R9,0) -> 1.181 | U9: =IFERROR((L9-V9)/V9,0) -> 0.1636 | V9: =L9/1.1636 -> 48972.998
A10: 45325 | B10: February | C10: Q1 | D10: 2024 | E10: North | F10: Delhi | G10: Karan Mehta | H10: Apparel | I10: Women's Kurti | J10: 249 | K10: 7316.92 | L10: =J10*K10 -> 1821913.1 | M10: =L10*0.7086 -> 1291007.6 | N10: =L10-M10 -> 530905.47 | O10: =IFERROR(N10/L10,0) -> 0.2914 | P10: New | Q10: Online | R10: =L10/(1+-0.1612) -> 2172047.1 | S10: =L10 -> 1821913.1 | T10: =IFERROR(S10/R10,0) -> 0.8388 | U10: =IFERROR((L10-V10)/V10,0) -> -0.1323 | V10: =L10/0.8677 -> 2099703.9
A11: 45330 | B11: February | C11: Q1 | D11: 2024 | E11: North | F11: Lucknow | G11: Arjun Verma | H11: Home Appliances | I11: Microwave Oven | J11: 444 | K11: 7474.07 | L11: =J11*K11 -> 3318487.1 | M11: =L11*0.74 -> 2455680.4 | N11: =L11-M11 -> 862806.64 | O11: =IFERROR(N11/L11,0) -> 0.26 | P11: New | Q11: Online | R11: =L11/(1+-0.079) -> 3603134.7 | S11: =L11 -> 3318487.1 | T11: =IFERROR(S11/R11,0) -> 0.921 | U11: =IFERROR((L11-V11)/V11,0) -> 0.186 | V11: =L11/1.186 -> 2798049.8
A12: 45348 | B12: February | C12: Q1 | D12: 2024 | E12: East | F12: Kolkata | G12: Karan Mehta | H12: Apparel | I12: Running Shoes | J12: 199 | K12: 4326.23 | L12: =J12*K12 -> 860919.77 | M12: =L12*0.7428 -> 639491.21 | N12: =L12-M12 -> 221428.56 | O12: =IFERROR(N12/L12,0) -> 0.2572 | P12: New | Q12: Offline | R12: =L12/(1+0.0941) -> 786874.85 | S12: =L12 -> 860919.77 | T12: =IFERROR(S12/R12,0) -> 1.0941 | U12: =IFERROR((L12-V12)/V12,0) -> -0.1783 | V12: =L12/0.8217 -> 1047730
A13: 45350 | B13: February | C13: Q1 | D13: 2024 | E13: Central | F13: Raipur | G13: Vikram Rao | H13: FMCG | I13: Skin Care Cream | J13: 412 | K13: 2667.03 | L13: =J13*K13 -> 1098816.4 | M13: =L13*0.5187 -> 569956.05 | N13: =L13-M13 -> 528860.31 | O13: =IFERROR(N13/L13,0) -> 0.4813 | P13: New | Q13: Online | R13: =L13/(1+0.1812) -> 930254.28 | S13: =L13 -> 1098816.4 | T13: =IFERROR(S13/R13,0) -> 1.1812 | U13: =IFERROR((L13-V13)/V13,0) -> 0.1256 | V13: =L13/1.1256 -> 976205.01
A14: 45353 | B14: March | C14: Q1 | D14: 2024 | E14: Central | F14: Nagpur | G14: Ananya Iyer | H14: Home Appliances | I14: Microwave Oven | J14: 126 | K14: 6869.34 | L14: =J14*K14 -> 865536.84 | M14: =L14*0.5218 -> 451637.12 | N14: =L14-M14 -> 413899.72 | O14: =IFERROR(N14/L14,0) -> 0.4782 | P14: New | Q14: Offline | R14: =L14/(1+0.0704) -> 808610.65 | S14: =L14 -> 865536.84 | T14: =IFERROR(S14/R14,0) -> 1.0704 | U14: =IFERROR((L14-V14)/V14,0) -> 0.2121 | V14: =L14/1.2121 -> 714080.39
A15: 45371 | B15: March | C15: Q1 | D15: 2024 | E15: North | F15: Lucknow | G15: Ananya Iyer | H15: Home Appliances | I15: Washing Machine 7kg | J15: 488 | K15: 6916.09 | L15: =J15*K15 -> 3375051.9 | M15: =L15*0.5255 -> 1773589.8 | N15: =L15-M15 -> 1601462.1 | O15: =IFERROR(N15/L15,0) -> 0.4745 | P15: Existing | Q15: Online | R15: =L15/(1+0.1128) -> 3032936.7 | S15: =L15 -> 3375051.9 | T15: =IFERROR(S15/R15,0) -> 1.1128 | U15: =IFERROR((L15-V15)/V15,0) -> -0.1099 | V15: =L15/0.8901 -> 3791767.1
A16: 45386 | B16: April | C16: Q2 | D16: 2024 | E16: North | F16: Lucknow | G16: Sneha Kapoor | H16: Electronics | I16: Laptop Pro 14 | J16: 466 | K16: 1790.24 | L16: =J16*K16 -> 834251.84 | M16: =L16*0.746 -> 622351.87 | N16: =L16-M16 -> 211899.97 | O16: =IFERROR(N16/L16,0) -> 0.254 | P16: New | Q16: Offline | R16: =L16/(1+-0.1804) -> 1017876.8 | S16: =L16 -> 834251.84 | T16: =IFERROR(S16/R16,0) -> 0.8196 | U16: =IFERROR((L16-V16)/V16,0) -> 0.1563 | V16: =L16/1.1563 -> 721483.91
A17: 45388 | B17: April | C17: Q2 | D17: 2024 | E17: South | F17: Bengaluru | G17: Vikram Rao | H17: Electronics | I17: Laptop Pro 14 | J17: 254 | K17: 6748.62 | L17: =J17*K17 -> 1714149.5 | M17: =L17*0.6744 -> 1156022.4 | N17: =L17-M17 -> 558127.07 | O17: =IFERROR(N17/L17,0) -> 0.3256 | P17: Existing | Q17: Online | R17: =L17/(1+0.1607) -> 1476823.9 | S17: =L17 -> 1714149.5 | T17: =IFERROR(S17/R17,0) -> 1.1607 | U17: =IFERROR((L17-V17)/V17,0) -> 0.181 | V17: =L17/1.181 -> 1451439
A18: 45413 | B18: May | C18: Q2 | D18: 2024 | E18: East | F18: Bhubaneswar | G18: Karan Mehta | H18: FMCG | I18: Skin Care Cream | J18: 36 | K18: 6590.07 | L18: =J18*K18 -> 237242.52 | M18: =L18*0.6397 -> 151764.04 | N18: =L18-M18 -> 85478.48 | O18: =IFERROR(N18/L18,0) -> 0.3603 | P18: New | Q18: Online | R18: =L18/(1+-0.0285) -> 244202.29 | S18: =L18 -> 237242.52 | T18: =IFERROR(S18/R18,0) -> 0.9715 | U18: =IFERROR((L18-V18)/V18,0) -> -0.0039 | V18: =L18/0.9961 -> 238171.39
A19: 45426 | B19: May | C19: Q2 | D19: 2024 | E19: East | F19: Kolkata | G19: Nikhil Gupta | H19: FMCG | I19: Organic Tea | J19: 469 | K19: 5825.37 | L19: =J19*K19 -> 2732098.5 | M19: =L19*0.6296 -> 1720129.2 | N19: =L19-M19 -> 1011969.3 | O19: =IFERROR(N19/L19,0) -> 0.3704 | P19: Existing | Q19: Offline | R19: =L19/(1+0.086) -> 2515744.5 | S19: =L19 -> 2732098.5 | T19: =IFERROR(S19/R19,0) -> 1.086 | U19: =IFERROR((L19-V19)/V19,0) -> -0.0525 | V19: =L19/0.9475 -> 2883481.3
A20: 45427 | B20: May | C20: Q2 | D20: 2024 | E20: West | F20: Pune | G20: Karan Mehta | H20: Electronics | I20: Smart Watch | J20: 388 | K20: 462.89 | L20: =J20*K20 -> 179601.32 | M20: =L20*0.6762 -> 121446.41 | N20: =L20-M20 -> 58154.907 | O20: =IFERROR(N20/L20,0) -> 0.3238 | P20: New | Q20: Offline | R20: =L20/(1+0.1531) -> 155755.2 | S20: =L20 -> 179601.32 | T20: =IFERROR(S20/R20,0) -> 1.1531 | U20: =IFERROR((L20-V20)/V20,0) -> 0.0397 | V20: =L20/1.0397 -> 172743.41
A21: 45433 | B21: May | C21: Q2 | D21: 2024 | E21: West | F21: Mumbai | G21: Rohan Sharma | H21: FMCG | I21: Packaged Snacks | J21: 410 | K21: 4584.92 | L21: =J21*K21 -> 1879817.2 | M21: =L21*0.6689 -> 1257409.7 | N21: =L21-M21 -> 622407.47 | O21: =IFERROR(N21/L21,0) -> 0.3311 | P21: Existing | Q21: Offline | R21: =L21/(1+-0.1645) -> 2249930.8 | S21: =L21 -> 1879817.2 | T21: =IFERROR(S21/R21,0) -> 0.8355 | U21: =IFERROR((L21-V21)/V21,0) -> 0.2463 | V21: =L21/1.2463 -> 1508318.4
A22: 45438 | B22: May | C22: Q2 | D22: 2024 | E22: South | F22: Hyderabad | G22: Nikhil Gupta | H22: Home Appliances | I22: Microwave Oven | J22: 97 | K22: 5002.45 | L22: =J22*K22 -> 485237.65 | M22: =L22*0.5011 -> 243152.59 | N22: =L22-M22 -> 242085.06 | O22: =IFERROR(N22/L22,0) -> 0.4989 | P22: New | Q22: Offline | R22: =L22/(1+0.0325) -> 469963.83 | S22: =L22 -> 485237.65 | T22: =IFERROR(S22/R22,0) -> 1.0325 | U22: =IFERROR((L22-V22)/V22,0) -> -0.0313 | V22: =L22/0.9687 -> 500916.33
A23: 45439 | B23: May | C23: Q2 | D23: 2024 | E23: East | F23: Bhubaneswar | G23: Arjun Verma | H23: Home Appliances | I23: Washing Machine 7kg | J23: 348 | K23: 4934.57 | L23: =J23*K23 -> 1717230.4 | M23: =L23*0.6951 -> 1193646.8 | N23: =L23-M23 -> 523583.54 | O23: =IFERROR(N23/L23,0) -> 0.3049 | P23: Existing | Q23: Online | R23: =L23/(1+0.0794) -> 1590912 | S23: =L23 -> 1717230.4 | T23: =IFERROR(S23/R23,0) -> 1.0794 | U23: =IFERROR((L23-V23)/V23,0) -> 0.2772 | V23: =L23/1.2772 -> 1344527.4
A24: 45439 | B24: May | C24: Q2 | D24: 2024 | E24: Central | F24: Nagpur | G24: Sneha Kapoor | H24: Furniture | I24: Wooden Dining Table | J24: 112 | K24: 1817.16 | L24: =J24*K24 -> 203521.92 | M24: =L24*0.6038 -> 122886.54 | N24: =L24-M24 -> 80635.385 | O24: =IFERROR(N24/L24,0) -> 0.3962 | P24: New | Q24: Online | R24: =L24/(1+0.0977) -> 185407.6 | S24: =L24 -> 203521.92 | T24: =IFERROR(S24/R24,0) -> 1.0977 | U24: =IFERROR((L24-V24)/V24,0) -> 0.1117 | V24: =L24/1.1117 -> 183072.7
A25: 45449 | B25: June | C25: Q2 | D25: 2024 | E25: Central | F25: Bhopal | G25: Vikram Rao | H25: Furniture | I25: Sofa Set 3-Seater | J25: 163 | K25: 5562.66 | L25: =J25*K25 -> 906713.58 | M25: =L25*0.5157 -> 467592.19 | N25: =L25-M25 -> 439121.39 | O25: =IFERROR(N25/L25,0) -> 0.4843 | P25: Existing | Q25: Offline | R25: =L25/(1+0.0512) -> 862550.97 | S25: =L25 -> 906713.58 | T25: =IFERROR(S25/R25,0) -> 1.0512 | U25: =IFERROR((L25-V25)/V25,0) -> -0.0404 | V25: =L25/0.9596 -> 944887.02
A26: 45450 | B26: June | C26: Q2 | D26: 2024 | E26: West | F26: Ahmedabad | G26: Rohan Sharma | H26: Electronics | I26: Laptop Pro 14 | J26: 321 | K26: 5481.05 | L26: =J26*K26 -> 1759417.1 | M26: =L26*0.7029 -> 1236694.2 | N26: =L26-M26 -> 522722.81 | O26: =IFERROR(N26/L26,0) -> 0.2971 | P26: Existing | Q26: Online | R26: =L26/(1+0.0493) -> 1676753.1 | S26: =L26 -> 1759417.1 | T26: =IFERROR(S26/R26,0) -> 1.0493 | U26: =IFERROR((L26-V26)/V26,0) -> -0.0531 | V26: =L26/0.9469 -> 1858081.2
A27: 45455 | B27: June | C27: Q2 | D27: 2024 | E27: North | F27: Chandigarh | G27: Nikhil Gupta | H27: Apparel | I27: Men's Formal Shirt | J27: 48 | K27: 2041.47 | L27: =J27*K27 -> 97990.56 | M27: =L27*0.5639 -> 55256.877 | N27: =L27-M27 -> 42733.683 | O27: =IFERROR(N27/L27,0) -> 0.4361 | P27: Existing | Q27: Online | R27: =L27/(1+-0.0063) -> 98611.814 | S27: =L27 -> 97990.56 | T27: =IFERROR(S27/R27,0) -> 0.9937 | U27: =IFERROR((L27-V27)/V27,0) -> 0.1934 | V27: =L27/1.1934 -> 82110.407
A28: 45458 | B28: June | C28: Q2 | D28: 2024 | E28: East | F28: Patna | G28: Karan Mehta | H28: Electronics | I28: Smart Watch | J28: 199 | K28: 2835.29 | L28: =J28*K28 -> 564222.71 | M28: =L28*0.6927 -> 390837.07 | N28: =L28-M28 -> 173385.64 | O28: =IFERROR(N28/L28,0) -> 0.3073 | P28: New | Q28: Offline | R28: =L28/(1+0.0984) -> 513676.9 | S28: =L28 -> 564222.71 | T28: =IFERROR(S28/R28,0) -> 1.0984 | U28: =IFERROR((L28-V28)/V28,0) -> -0.1314 | V28: =L28/0.8686 -> 649577.15
A29: 45461 | B29: June | C29: Q2 | D29: 2024 | E29: Central | F29: Bhopal | G29: Vikram Rao | H29: Electronics | I29: Smart Watch | J29: 400 | K29: 7697.64 | L29: =J29*K29 -> 3079056 | M29: =L29*0.7356 -> 2264953.6 | N29: =L29-M29 -> 814102.41 | O29: =IFERROR(N29/L29,0) -> 0.2644 | P29: New | Q29: Online | R29: =L29/(1+0.1487) -> 2680470.1 | S29: =L29 -> 3079056 | T29: =IFERROR(S29/R29,0) -> 1.1487 | U29: =IFERROR((L29-V29)/V29,0) -> -0.1015 | V29: =L29/0.8985 -> 3426884.8
A30: 45465 | B30: June | C30: Q2 | D30: 2024 | E30: West | F30: Pune | G30: Rohan Sharma | H30: Furniture | I30: Wooden Dining Table | J30: 416 | K30: 5931.37 | L30: =J30*K30 -> 2467449.9 | M30: =L30*0.5765 -> 1422484.9 | N30: =L30-M30 -> 1044965 | O30: =IFERROR(N30/L30,0) -> 0.4235 | P30: New | Q30: Online | R30: =L30/(1+-0.0992) -> 2739176.2 | S30: =L30 -> 2467449.9 | T30: =IFERROR(S30/R30,0) -> 0.9008 | U30: =IFERROR((L30-V30)/V30,0) -> 0.0171 | V30: =L30/1.0171 -> 2425965.9
A31: 45465 | B31: June | C31: Q2 | D31: 2024 | E31: Central | F31: Bhopal | G31: Vikram Rao | H31: Furniture | I31: Sofa Set 3-Seater | J31: 396 | K31: 3476.49 | L31: =J31*K31 -> 1376690 | M31: =L31*0.7031 -> 967950.77 | N31: =L31-M31 -> 408739.27 | O31: =IFERROR(N31/L31,0) -> 0.2969 | P31: Existing | Q31: Offline | R31: =L31/(1+0.1182) -> 1231166.2 | S31: =L31 -> 1376690 | T31: =IFERROR(S31/R31,0) -> 1.1182 | U31: =IFERROR((L31-V31)/V31,0) -> -0.0545 | V31: =L31/0.9455 -> 1456044.5
A32: 45465 | B32: June | C32: Q2 | D32: 2024 | E32: North | F32: Lucknow | G32: Priya Nair | H32: Furniture | I32: Wooden Dining Table | J32: 152 | K32: 3681.84 | L32: =J32*K32 -> 559639.68 | M32: =L32*0.6314 -> 353356.49 | N32: =L32-M32 -> 206283.19 | O32: =IFERROR(N32/L32,0) -> 0.3686 | P32: New | Q32: Offline | R32: =L32/(1+-0.141) -> 651501.37 | S32: =L32 -> 559639.68 | T32: =IFERROR(S32/R32,0) -> 0.859 | U32: =IFERROR((L32-V32)/V32,0) -> 0.2936 | V32: =L32/1.2936 -> 432621.89
A33: 45471 | B33: June | C33: Q2 | D33: 2024 | E33: Central | F33: Nagpur | G33: Karan Mehta | H33: Home Appliances | I33: Refrigerator 300L | J33: 413 | K33: 6224.78 | L33: =J33*K33 -> 2570834.1 | M33: =L33*0.5881 -> 1511907.6 | N33: =L33-M33 -> 1058926.6 | O33: =IFERROR(N33/L33,0) -> 0.4119 | P33: New | Q33: Offline | R33: =L33/(1+-0.1423) -> 2997358.2 | S33: =L33 -> 2570834.1 | T33: =IFERROR(S33/R33,0) -> 0.8577 | U33: =IFERROR((L33-V33)/V33,0) -> -0.0661 | V33: =L33/0.9339 -> 2752793.8
A34: 45472 | B34: June | C34: Q2 | D34: 2024 | E34: Central | F34: Nagpur | G34: Priya Nair | H34: FMCG | I34: Organic Tea | J34: 269 | K34: 6029.78 | L34: =J34*K34 -> 1622010.8 | M34: =L34*0.5186 -> 841174.81 | N34: =L34-M34 -> 780836.01 | O34: =IFERROR(N34/L34,0) -> 0.4814 | P34: New | Q34: Online | R34: =L34/(1+0.0081) -> 1608978.1 | S34: =L34 -> 1622010.8 | T34: =IFERROR(S34/R34,0) -> 1.0081 | U34: =IFERROR((L34-V34)/V34,0) -> -0.0735 | V34: =L34/0.9265 -> 1750686.3
A35: 45479 | B35: July | C35: Q3 | D35: 2024 | E35: Central | F35: Raipur | G35: Rohan Sharma | H35: FMCG | I35: Packaged Snacks | J35: 309 | K35: 2286.91 | L35: =J35*K35 -> 706655.19 | M35: =L35*0.549 -> 387953.7 | N35: =L35-M35 -> 318701.49 | O35: =IFERROR(N35/L35,0) -> 0.451 | P35: New | Q35: Offline | R35: =L35/(1+-0.1888) -> 871123.26 | S35: =L35 -> 706655.19 | T35: =IFERROR(S35/R35,0) -> 0.8112 | U35: =IFERROR((L35-V35)/V35,0) -> 0.0709 | V35: =L35/1.0709 -> 659870.38
A36: 45487 | B36: July | C36: Q3 | D36: 2024 | E36: Central | F36: Nagpur | G36: Arjun Verma | H36: Apparel | I36: Women's Kurti | J36: 83 | K36: 2849.49 | L36: =J36*K36 -> 236507.67 | M36: =L36*0.6248 -> 147769.99 | N36: =L36-M36 -> 88737.678 | O36: =IFERROR(N36/L36,0) -> 0.3752 | P36: New | Q36: Online | R36: =L36/(1+0.172) -> 201798.35 | S36: =L36 -> 236507.67 | T36: =IFERROR(S36/R36,0) -> 1.172 | U36: =IFERROR((L36-V36)/V36,0) -> 0.1589 | V36: =L36/1.1589 -> 204079.45
A37: 45489 | B37: July | C37: Q3 | D37: 2024 | E37: East | F37: Kolkata | G37: Nikhil Gupta | H37: Electronics | I37: Laptop Pro 14 | J37: 30 | K37: 1927.13 | L37: =J37*K37 -> 57813.9 | M37: =L37*0.6797 -> 39296.108 | N37: =L37-M37 -> 18517.792 | O37: =IFERROR(N37/L37,0) -> 0.3203 | P37: Existing | Q37: Online | R37: =L37/(1+0.0392) -> 55633.083 | S37: =L37 -> 57813.9 | T37: =IFERROR(S37/R37,0) -> 1.0392 | U37: =IFERROR((L37-V37)/V37,0) -> 0.0406 | V37: =L37/1.0406 -> 55558.236
A38: 45494 | B38: July | C38: Q3 | D38: 2024 | E38: West | F38: Pune | G38: Nikhil Gupta | H38: Home Appliances | I38: Refrigerator 300L | J38: 260 | K38: 5253.88 | L38: =J38*K38 -> 1366008.8 | M38: =L38*0.6619 -> 904161.22 | N38: =L38-M38 -> 461847.58 | O38: =IFERROR(N38/L38,0) -> 0.3381 | P38: New | Q38: Online | R38: =L38/(1+-0.0556) -> 1446430.3 | S38: =L38 -> 1366008.8 | T38: =IFERROR(S38/R38,0) -> 0.9444 | U38: =IFERROR((L38-V38)/V38,0) -> 0.0934 | V38: =L38/1.0934 -> 1249322.1
A39: 45499 | B39: July | C39: Q3 | D39: 2024 | E39: East | F39: Bhubaneswar | G39: Priya Nair | H39: Home Appliances | I39: Microwave Oven | J39: 453 | K39: 7438.71 | L39: =J39*K39 -> 3369735.6 | M39: =L39*0.647 -> 2180219 | N39: =L39-M39 -> 1189516.7 | O39: =IFERROR(N39/L39,0) -> 0.353 | P39: Existing | Q39: Offline | R39: =L39/(1+0.1472) -> 2937356.7 | S39: =L39 -> 3369735.6 | T39: =IFERROR(S39/R39,0) -> 1.1472 | U39: =IFERROR((L39-V39)/V39,0) -> 0.1626 | V39: =L39/1.1626 -> 2898448
A40: 45519 | B40: August | C40: Q3 | D40: 2024 | E40: North | F40: Chandigarh | G40: Priya Nair | H40: Electronics | I40: Smart Watch | J40: 150 | K40: 4362.13 | L40: =J40*K40 -> 654319.5 | M40: =L40*0.5897 -> 385852.21 | N40: =L40-M40 -> 268467.29 | O40: =IFERROR(N40/L40,0) -> 0.4103 | P40: Existing | Q40: Online | R40: =L40/(1+0.0492) -> 623636.58 | S40: =L40 -> 654319.5 | T40: =IFERROR(S40/R40,0) -> 1.0492 | U40: =IFERROR((L40-V40)/V40,0) -> -0.0545 | V40: =L40/0.9455 -> 692035.43
...

Sheet KPI_Summary
A1: Metric | B1: Value
A2: Total Revenue | B2: =SUM(Sales_Data!L2:L151) -> 1.4744626e+08
A3: Total Cost | B3: =SUM(Sales_Data!M2:M151) -> 92459619
A4: Total Profit | B4: =SUM(Sales_Data!N2:N151) -> 54986639
A5: Overall Profit Margin % | B5: =SUM(Sales_Data!N2:N151)/SUM(Sales_Data!L2:L151) -> 0.37292665
A6: Total Units Sold | B6: =SUM(Sales_Data!J2:J151) -> 35930
A7: Total Target Sales | B7: =SUM(Sales_Data!R2:R151) -> 1.4945793e+08
A8: Total Actual Sales | B8: =SUM(Sales_Data!S2:S151) -> 1.4744626e+08
A9: Overall Achievement % | B9: =SUM(Sales_Data!S2:S151)/SUM(Sales_Data!R2:R151) -> 0.98654024
A10: Average Growth % | B10: =AVERAGE(Sales_Data!U2:U151) -> 0.038638
